Workbook

Sheet Sheet1
A1: 2025 クリスマスライブ TT
B2: バンド名 | C2: メンバー数 | D2: 曲数 | E2: 開始時間 | F2: ~ | G2: 終了時間
B3: リハ
B4: 集合～準備 | E4: 0.375 | F4: ~ | G4: 0.41666667
A5: 11 | B5: ALIをやりたいのだ | C5: 10 | D5: 3 | E5: =G4 -> 0.41666667 | F5: ~ | G5: =SUM(E5, Sheet2!A4) -> 0.43402778
B6: 転換 | E6: =G5 -> 0.43402778 | F6: ~ | G6: =SUM(E6, Sheet2!A5) -> 0.4375
A7: 10 | B7: 鶴は千年 亀は万年 俺らは200種類おんねん | C7: 6 | D7: 2 | E7: =G6 -> 0.4375 | F7: ~ | G7: =SUM(E7, Sheet2!A6) -> 0.45138889
B8: 転換 | E8: =G7 -> 0.45138889 | F8: ~ | G8: =SUM(E8, Sheet2!A7) -> 0.45486111
A9: 9 | B9: もるふぉにか | C9: 5 | D9: 3 | E9: =G8 -> 0.45486111 | F9: ~ | G9: =SUM(E9, Sheet2!A8) -> 0.46875
B10: 転換 | E10: =G9 -> 0.46875 | F10: ~ | G10: =SUM(E10, Sheet2!A9) -> 0.47222222
A11: 8 | B11: Dreamerzzz | C11: 4 | D11: 2 | E11: =G10 -> 0.47222222 | F11: ~ | G11: =SUM(E11, Sheet2!A10) -> 0.48611111
B12: 転換 | E12: =G11 -> 0.48611111 | F12: ~ | G12: =SUM(E12, Sheet2!A11) -> 0.48958333
A13: 7 | B13: リアと愉快な仲間たち | C13: 5 | D13: 2 | E13: =G12 -> 0.48958333 | F13: ~ | G13: =SUM(E13, Sheet2!A12) -> 0.50347222
B14: 転換 | E14: =G13 -> 0.50347222 | F14: ~ | G14: =SUM(E14, Sheet2!A13) -> 0.50694444
A15: 6 | B15: わかばちゃんｽﾞ🔰 | C15: 5 | D15: 1 | E15: =G14 -> 0.50694444 | F15: ~ | G15: =SUM(E15, Sheet2!A14) -> 0.52083333
B16: 転換 | E16: =G15 -> 0.52083333 | F16: ~ | G16: =SUM(E16, Sheet2!A15) -> 0.52430556
A17: 5 | B17: ホルンアンサンブル | C17: 3 | D17: 2 | E17: =G16 -> 0.52430556 | F17: ~ | G17: =SUM(E17, Sheet2!A16) -> 0.53125
B18: 転換 | E18: =G17 -> 0.53125 | F18: ~ | G18: =SUM(E18, Sheet2!A17) -> 0.53472222
A19: 4 | B19: AONOKASEI | C19: 5 | D19: 2 | E19: =G18 -> 0.53472222 | F19: ~ | G19: =SUM(E19, Sheet2!A18) -> 0.54861111
B20: 転換 | E20: =G19 -> 0.54861111 | F20: ~ | G20: =SUM(E20, Sheet2!A19) -> 0.55208333
A21: 3 | B21: ロビンソン | C21: 5 | D21: 1 | E21: =G20 -> 0.55208333 | F21: ~ | G21: =SUM(E21, Sheet2!A20) -> 0.5625
B22: 転換 | E22: =G21 -> 0.5625 | F22: ~ | G22: =SUM(E22, Sheet2!A21) -> 0.56597222
A23: 2 | B23: 群青のクリスマス | C23: 5 | D23: 1 | E23: =G22 -> 0.56597222 | F23: ~ | G23: =SUM(E23, Sheet2!A22) -> 0.57638889
B24: 転換 | E24: =G23 -> 0.57638889 | F24: ~ | G24: =SUM(E24, Sheet2!A23) -> 0.57986111
A25: 1 | B25: こんにちワールド | C25: 5 | D25: 1 | E25: =G24 -> 0.57986111 | F25: ~ | G25: =SUM(E25, Sheet2!A24) -> 0.59027778
B26: 休憩 | E26: =G25 -> 0.59027778 | F26: ~ | G26: =SUM(E26, Sheet2!A25) -> 0.59722222
B27: 本番
A28: 1 | B28: こんにちワールド | C28: 5 | D28: 1 | E28: =G26 -> 0.59722222 | F28: ~ | G28: =SUM(E28, Sheet2!A27) -> 0.60416667
B29: 転換 | E29: =G28 -> 0.60416667 | F29: ~ | G29: =SUM(E29, Sheet2!A28) -> 0.60763889
A30: 2 | B30: 群青のクリスマス | C30: 5 | D30: 1 | E30: =G29 -> 0.60763889 | F30: ~ | G30: =SUM(E30, Sheet2!A29) -> 0.61458333
B31: 転換 | E31: =G30 -> 0.61458333 | F31: ~ | G31: =SUM(E31, Sheet2!A30) -> 0.61805556
A32: 3 | B32: ロビンソン | C32: 5 | D32: 1 | E32: =G31 -> 0.61805556 | F32: ~ | G32: =SUM(E32, Sheet2!A31) -> 0.625
B33: 転換 | E33: =G32 -> 0.625 | F33: ~ | G33: =SUM(E33, Sheet2!A32) -> 0.62847222
A34: 4 | B34: AONOKASEI | C34: 5 | D34: 2 | E34: =G33 -> 0.62847222 | F34: ~ | G34: =SUM(E34, Sheet2!A33) -> 0.63541667
B35: 転換 | E35: =G34 -> 0.63541667 | F35: ~ | G35: =SUM(E35, Sheet2!A34) -> 0.63888889
A36: 5 | B36: ホルンアンサンブル | C36: 3 | D36: 2 | E36: =G35 -> 0.63888889 | F36: ~ | G36: =SUM(E36, Sheet2!A35) -> 0.64583333
B37: 転換 | E37: =G36 -> 0.64583333 | F37: ~ | G37: =SUM(E37, Sheet2!A36) -> 0.64930556
A38: 6 | B38: わかばちゃんｽﾞ🔰 | C38: 5 | D38: 1 | E38: =G37 -> 0.64930556 | F38: ~ | G38: =SUM(E38, Sheet2!A37) -> 0.65625
B39: 転換 | E39: =G38 -> 0.65625 | F39: ~ | G39: =SUM(E39, Sheet2!A38) -> 0.65972222
A40: 7 | B40: リアと愉快な仲間たち | C40: 5 | D40: 2 | E40: =G39 -> 0.65972222 | F40: ~ | G40: =SUM(E40, Sheet2!A39) -> 0.67013889
...

Sheet Sheet2
A1: 持ち時間
A3: 0.041666667
A4: 0.017361111
A5: 0.0034722222
A6: 0.013888889
A7: 0.0034722222
A8: 0.013888889
A9: 0.0034722222
A10: 0.013888889
A11: 0.0034722222
A12: 0.013888889
A13: 0.0034722222
A14: 0.013888889
... A48: 0.041666667
B51: リハ
B52: 本番
B53: トータル
